Workbook

Sheet All Sessions
A1: Event No. | B1: Session | C1: Event Title | D1: Event Series / Programme | E1: Delivery Mode | F1: Venue / Location (as listed) | G1: Date | H1: Day | I1: Start Time | J1: End Time | K1: Duration (hrs) | L1: Description | M1: Featured Organisation (logo shown) | N1: Listing Page (results) | O1: Source
A2: 1 | B2: 1 of 3 | C2: eCareersGrad MasterClass: UK Grad Job & Internship Success: The Essential Guide | D2: eCareersGrad MasterClass | E2: Virtual | F2: Virtual event / Online webinar | G2: 46303 | H2: =TEXT(G2,"ddd") -> Thu | I2: 0.50694444 | J2: 0.54166667 | K2: =ROUND((J2-I2)*24,2) -> 0.83 | L2: An information session delivered by eCareersGrad with time for questions and answers. | N2: 1-100 | O2: UCL Careers (uclcareers.targetconnect.net), captured 13-Oct-2026
A3: 1 | B3: 2 of 3 | C3: eCareersGrad MasterClass: UK Grad Job & Internship Success: The Essential Guide | D3: eCareersGrad MasterClass | E3: Virtual | F3: Virtual event / Online webinar | G3: 46309 | H3: =TEXT(G3,"ddd") -> Wed | I3: 0.50694444 | J3: 0.54166667 | K3: =ROUND((J3-I3)*24,2) -> 0.83 | L3: An information session delivered by eCareersGrad with time for questions and answers. | N3: 1-100 | O3: UCL Careers (uclcareers.targetconnect.net), captured 13-Oct-2026
A4: 1 | B4: 3 of 3 | C4: eCareersGrad MasterClass: UK Grad Job & Internship Success: The Essential Guide | D4: eCareersGrad MasterClass | E4: Virtual | F4: Virtual event / Online webinar | G4: 46323 | H4: =TEXT(G4,"ddd") -> Wed | I4: 0.50694444 | J4: 0.54166667 | K4: =ROUND((J4-I4)*24,2) -> 0.83 | L4: An information session delivered by eCareersGrad with time for questions and answers. | N4: 1-100 | O4: UCL Careers (uclcareers.targetconnect.net), captured 13-Oct-2026
A5: 2 | B5: 1 of 6 | C5: eCareersGrad MasterClass: International Students: Target the Right UK Employer SPONSOR | D5: eCareersGrad MasterClass | E5: Virtual | F5: Virtual event / Online webinar | G5: 46303 | H5: =TEXT(G5,"ddd") -> Thu | I5: 0.54861111 | J5: 0.58333333 | K5: =ROUND((J5-I5)*24,2) -> 0.83 | L5: An information session delivered by eCareersGrad with time for questions and answers. | N5: 1-100 | O5: UCL Careers (uclcareers.targetconnect.net), captured 13-Oct-2026
A6: 2 | B6: 2 of 6 | C6: eCareersGrad MasterClass: International Students: Target the Right UK Employer SPONSOR | D6: eCareersGrad MasterClass | E6: Virtual | F6: Virtual event / Online webinar | G6: 46309 | H6: =TEXT(G6,"ddd") -> Wed | I6: 0.54861111 | J6: 0.58333333 | K6: =ROUND((J6-I6)*24,2) -> 0.83 | L6: An information session delivered by eCareersGrad with time for questions and answers. | N6: 1-100 | O6: UCL Careers (uclcareers.targetconnect.net), captured 13-Oct-2026
A7: 2 | B7: 3 of 6 | C7: eCareersGrad MasterClass: International Students: Target the Right UK Employer SPONSOR | D7: eCareersGrad MasterClass | E7: Virtual | F7: Virtual event / Online webinar | G7: 46315 | H7: =TEXT(G7,"ddd") -> Tue | I7: 0.54861111 | J7: 0.58333333 | K7: =ROUND((J7-I7)*24,2) -> 0.83 | L7: An information session delivered by eCareersGrad with time for questions and answers. | N7: 1-100 | O7: UCL Careers (uclcareers.targetconnect.net), captured 13-Oct-2026
A8: 2 | B8: 4 of 6 | C8: eCareersGrad MasterClass: International Students: Target the Right UK Employer SPONSOR | D8: eCareersGrad MasterClass | E8: Virtual | F8: Virtual event / Online webinar | G8: 46323 | H8: =TEXT(G8,"ddd") -> Wed | I8: 0.54861111 | J8: 0.58333333 | K8: =ROUND((J8-I8)*24,2) -> 0.83 | L8: An information session delivered by eCareersGrad with time for questions and answers. | N8: 1-100 | O8: UCL Careers (uclcareers.targetconnect.net), captured 13-Oct-2026
A9: 2 | B9: 5 of 6 | C9: eCareersGrad MasterClass: International Students: Target the Right UK Employer SPONSOR | D9: eCareersGrad MasterClass | E9: Virtual | F9: Virtual event / Online webinar | G9: 46335 | H9: =TEXT(G9,"ddd") -> Mon | I9: 0.54861111 | J9: 0.58333333 | K9: =ROUND((J9-I9)*24,2) -> 0.83 | L9: An information session delivered by eCareersGrad with time for questions and answers. | N9: 1-100 | O9: UCL Careers (uclcareers.targetconnect.net), captured 13-Oct-2026
A10: 2 | B10: 6 of 6 | C10: eCareersGrad MasterClass: International Students: Target the Right UK Employer SPONSOR | D10: eCareersGrad MasterClass | E10: Virtual | F10: Virtual event / Online webinar | G10: 46352 | H10: =TEXT(G10,"ddd") -> Thu | I10: 0.54861111 | J10: 0.58333333 | K10: =ROUND((J10-I10)*24,2) -> 0.83 | L10: An information session delivered by eCareersGrad with time for questions and answers. | N10: 1-100 | O10: UCL Careers (uclcareers.targetconnect.net), captured 13-Oct-2026
A11: 3 | B11: 1 of 1 | C11: Career Lab - Networking Preparation and Practice | D11: Career Lab | E11: On Campus | F11: On Campus: Canary Wharf Level 49, 49.02E Seminar Room | G11: 46308 | H11: =TEXT(G11,"ddd") -> Tue | I11: 0.39583333 | J11: 0.45833333 | K11: =ROUND((J11-I11)*24,2) -> 1.5 | L11: Work on your elevator pitch and practice your networking skills to make a fantastic first impression with employers. | N11: 1-100 | O11: UCL Careers (uclcareers.targetconnect.net), captured 13-Oct-2026
A12: 4 | B12: 1 of 1 | C12: Discover CASETiFY: Global Management Trainee Program 2027 Information Session | D12: Other / Employer-led event | E12: Virtual | F12: Virtual event / Online webinar | G12: 46308 | H12: =TEXT(G12,"ddd") -> Tue | I12: 0.5 | J12: 0.5625 | K12: =ROUND((J12-I12)*24,2) -> 1.5 | L12: Join us to learn more about CASETiFY's rapid global growth, hear first-hand experiences from our current Management Trainees, and get exclusive tips on how to apply for the 2027 intake. | N12: 1-100 | O12: UCL Careers (uclcareers.targetconnect.net), captured 13-Oct-2026
A13: 5 | B13: 1 of 1 | C13: Skills East: Online Job search strategy and LinkedIn | D13: Skills East | E13: Virtual | F13: Virtual event / Online webinar | G13: 46308 | H13: =TEXT(G13,"ddd") -> Tue | I13: 0.5 | J13: 0.54166667 | K13: =ROUND((J13-I13)*24,2) -> 1 | L13: In this online session you will have the opportunity to learn about building a job search strategy. This session will help you in terms of applications for jobs or internships as well as using LinkedIn as part of this process. | N13: 1-100 | O13: UCL Careers (uclcareers.targetconnect.net), captured 13-Oct-2026
A14: 6 | B14: 1 of 1 | C14: Career Essentials Group Work: CV Session | D14: Career Essentials Group Work | E14: On Campus | F14: On Campus: UCL Careers - 4th Floor Seminar Room (413) | G14: 46308 | H14: =TEXT(G14,"ddd") -> Tue | I14: 0.54166667 | J14: 0.57638889 | K14: =ROUND((J14-I14)*24,2) -> 0.83 | L14: Small group work Career Essentials session focusing on learning the key concepts that make up a good CV and getting feedback on your own CV from UCL Careers staff and peers. | N14: 1-100 | O14: UCL Careers (uclcareers.targetconnect.net), captured 13-Oct-2026
A15: 7 | B15: 1 of 1 | C15: Career Essentials: Improve Your CV | D15: Career Essentials | E15: Not stated | G15: 46308 | H15: =TEXT(G15,"ddd") -> Tue | I15: 0.54166667 | J15: 0.58333333 | K15: =ROUND((J15-I15)*24,2) -> 1 | L15: Strengthen your CV by learning how to grab an employer's interest and showcase your most relevant experiences. | N15: 1-100 | O15: UCL Careers (uclcareers.targetconnect.net), captured 13-Oct-2026
A16: 8 | B16: 1 of 1 | C16: Life & Health Sciences: Job Hunting and LinkedIn | D16: Life & Health Sciences | E16: Virtual | F16: Virtual event / Online webinar | G16: 46308 | H16: =TEXT(G16,"ddd") -> Tue | I16: 0.70833333 | J16: 0.75 | K16: =ROUND((J16-I16)*24,2) -> 1 | L16: Make LinkedIn work for your career. This session for Life and Health Sciences students explores how to find jobs, research organisations and professionals, uncover hidden opportunities, and strengthen your personal brand. | N16: 1-100 | O16: UCL Careers (uclcareers.targetconnect.net), captured 13-Oct-2026
A17: 9 | B17: 1 of 1 | C17: Meet the Deloitte Team at UCL East | D17: Other / Employer-led event | E17: On Campus | F17: UCL East Campus: Marshgate Building: Room 118 | G17: 46308 | H17: =TEXT(G17,"ddd") -> Tue | I17: 0.75 | J17: 0.875 | K17: =ROUND((J17-I17)*24,2) -> 3 | L17: Explore career journeys, develop your interview skills and practise with Deloitte | N17: 1-100 | O17: UCL Careers (uclcareers.targetconnect.net), captured 13-Oct-2026
A18: 10 | B18: 1 of 1 | C18: Buy Side Panel - Investment, Risk and Infrastructure Credit | D18: Other / Employer-led event | E18: On Campus | F18: On Campus: Canary Wharf Level 49, 49.01 Teaching Room | G18: 46309 | H18: =TEXT(G18,"ddd") -> Wed | I18: 0.53125 | J18: 0.59375 | K18: =ROUND((J18-I18)*24,2) -> 1.5 | L18: Senior professionals from Edmond De Rothschild, Janus Henderson, and Millennium share insights from their careers, take questions from the audience. There will also be time for more informal networking. | N18: 1-100 | O18: UCL Careers (uclcareers.targetconnect.net), captured 13-Oct-2026
A19: 11 | B19: 1 of 1 | C19: Overview of Global Consulting with James Brown from Savitas | D19: Other / Employer-led event | E19: Virtual | F19: Virtual event / Online webinar | G19: 46309 | H19: =TEXT(G19,"ddd") -> Wed | I19: 0.53125 | J19: 0.59375 | K19: =ROUND((J19-I19)*24,2) -> 1.5 | L19: Explore the range of options in and ways to enter the consulting industry in a global context | N19: 1-100 | O19: UCL Careers (uclcareers.targetconnect.net), captured 13-Oct-2026
A20: 12 | B20: 1 of 1 | C20: Employer-Led Skills Panel : Succeeding at Interviews with graduate recruiters | D20: Employer-led Skills Programme | E20: On Campus | F20: On Campus: UCL Careers - 4th Floor Seminar Room (413) | G20: 46309 | H20: =TEXT(G20,"ddd") -> Wed | I20: 0.54166667 | J20: 0.60416667 | K20: =ROUND((J20-I20)*24,2) -> 1.5 | L20: Employer-led skills panel discussion on how to succeed at interview with graduate employers | N20: 1-100 | O20: UCL Careers (uclcareers.targetconnect.net), captured 13-Oct-2026
A21: 13 | B21: 1 of 1 | C21: Career Essentials Group Work: Using STAR to Showcase Skills | D21: Career Essentials Group Work | E21: Virtual | F21: Virtual event / Online webinar | G21: 46309 | H21: =TEXT(G21,"ddd") -> Wed | I21: 0.54166667 | J21: 0.57638889 | K21: =ROUND((J21-I21)*24,2) -> 0.83 | L21: Small group work Career Essentials session focusing on learning the STAR technique, which can be used as a tool during interviews to help answer questions and showcase your skills. | N21: 1-100 | O21: UCL Careers (uclcareers.targetconnect.net), captured 13-Oct-2026
A22: 14 | B22: 1 of 1 | C22: Procter & Gamble Employer Spotlight: Graduate Careers & Recruitment | D22: Other / Employer-led event | E22: On Campus | F22: On Campus: Canary Wharf Level 50, SW54 Lecture Theatre | G22: 46309 | H22: =TEXT(G22,"ddd") -> Wed | I22: 0.54166667 | J22: 0.58333333 | K22: =ROUND((J22-I22)*24,2) -> 1 | L22: Join representatives from Procter & Gamble (P&G) to gain insight into careers, graduate recruitment and leadership development at one of the world's leading consumer goods companies. The session will provide an overview of opportunities available now | N22: 1-100 | O22: UCL Careers (uclcareers.targetconnect.net), captured 13-Oct-2026
A23: 15 | B23: 1 of 1 | C23: Shape Your International Future: HKU Business School Masters Info Session | D23: Other / Employer-led event | E23: On Campus | F23: On Campus: IOE - 20 Bedford Way C3.11 | G23: 46309 | H23: =TEXT(G23,"ddd") -> Wed | I23: 0.55208333 | J23: 0.61458333 | K23: =ROUND((J23-I23)*24,2) -> 1.5 | L23: Thinking about postgraduate study outside the UK and how to stand out in today's competitive job market? | N23: 1-100 | O23: UCL Careers (uclcareers.targetconnect.net), captured 13-Oct-2026
A24: 16 | B24: 1 of 1 | C24: Expedia Group Internship Insight Day (Office Visit) | D24: Other / Employer-led event | E24: Off Campus | F24: Off Campus | G24: 46309 | H24: =TEXT(G24,"ddd") -> Wed | I24: 0.57291667 | J24: 0.66666667 | K24: =ROUND((J24-I24)*24,2) -> 2.25 | L24: Are you graduating in 2028 and curious about what an internship at Expedia Group could look like? Join the Expedia Group for an exciting and immersive afternoon designed to set you up for success and help you prepare for your internship application. | N24: 1-100 | O24: UCL Careers (uclcareers.targetconnect.net), captured 13-Oct-2026
A25: 17 | B25: 1 of 1 | C25: Being Self-Employed/Freelancing Your Way: Different Brains, Different Ways of Working | D25: Other / Employer-led event | E25: Virtual | F25: Virtual event / Online webinar | G25: 46309 | H25: =TEXT(G25,"ddd") -> Wed | I25: 0.58333333 | J25: 0.64583333 | K25: =ROUND((J25-I25)*24,2) -> 1.5 | L25: This interactive workshop explores how neurodivergent people can build freelance (self-employed) and independent careers around the ways they work best when working in the Creative and Cultural Industries. | N25: 1-100 | O25: UCL Careers (uclcareers.targetconnect.net), captured 13-Oct-2026
A26: 18 | B26: 1 of 1 | C26: WORKING IN A GLOBAL WORLD - 2: How to Better Navigate a Complex World | D26: Working in a Global World | E26: On Campus | F26: On Campus: UCL Careers - 4th Floor Seminar Room (413) | G26: 46309 | H26: =TEXT(G26,"ddd") -> Wed | I26: 0.60416667 | J26: 0.70833333 | K26: =ROUND((J26-I26)*24,2) -> 2.5 | L26: The second session in the Cross-Cultural Communication strand is a deeper dive into beliefs, values, identity, and how they intersect. You will walk out the door with more frameworks to start using in your own life. | N26: 1-100 | O26: UCL Careers (uclcareers.targetconnect.net), captured 13-Oct-2026
A27: 19 | B27: 1 of 1 | C27: Get Hired! - Online Tests and Video Interview Prep | D27: Get Hired! | E27: On Campus | F27: On Campus: Canary Wharf Level 49, 49.01 Teaching Room | G27: 46309 | H27: =TEXT(G27,"ddd") -> Wed | I27: 0.60416667 | J27: 0.66666667 | K27: =ROUND((J27-I27)*24,2) -> 1.5 | L27: Work on your elevator pitch and practice your networking skills to make a fantastic first impression with employers. | N27: 1-100 | O27: UCL Careers (uclcareers.targetconnect.net), captured 13-Oct-2026
... A34: 26 | B34: 1 of 1 | C34: Launch Your Career with AlphaSights Asia - On-the-Spot Interviews Available | D34: Other / Employer-led event | E34: On Campus | F34: On Campus: Canary Wharf Level 49, 49.02 Teaching Room | G34: 46310 | H34: =TEXT(G34,"ddd") -> Thu | I34: 0.76041667 | J34: 0.80208333 | K34: =ROUND((J34-I34)*24,2) -> 1 | L34: Join us for an exclusive employer presentation hosted by AlphaSights, a global information services company specialising in connecting clients with expert knowledge to support informed business decisions. | N34: 1-100 | O34: UCL Careers (uclcareers.targetconnect.net), captured 13-Oct-2026
A35: 27 | B35: 1 of 1 | C35: Career Essentials: Application Forms and Cover Letters | D35: Career Essentials | E35: Not stated | G35: 46311 | H35: =TEXT(G35,"ddd") -> Fri | I35: 0.54166667 | J35: 0.58333333 | K35: =ROUND((J35-I35)*24,2) -> 1 | L35: Discover how to showcase your motivation and competency-based skills in your cover letter and on application materials. | N35: 1-100 | O35: UCL Careers (uclcareers.targetconnect.net), captured 13-Oct-2026
A36: 28 | B36: 1 of 1 | C36: Employer-led Skills Programme: One to One CV & Application Checking with Amazon | D36: Employer-led Skills Programme | E36: On Campus | F36: On Campus: UCL Careers (2) | G36: 46311 | H36: =TEXT(G36,"ddd") -> Fri | I36: 0.58333333 | J36: 0.70138889 | K36: =ROUND((J36-I36)*24,2) -> 2.83 | L36: Want expert employer feedback on your CV or application before you submit it? Participate in a one-to-one CV & Application Checking with a graduate employer. | N36: 1-100 | O36: UCL Careers (uclcareers.targetconnect.net), captured 13-Oct-2026
A37: 29 | B37: 1 of 1 | C37: Museum Collections in Practice: Careers, Collaboration and Decision-Making | D37: Other / Employer-led event | E37: On Campus | F37: On Campus: IOE - 20 Bedford Way - Room 822 | G37: 46311 | H37: =TEXT(G37,"ddd") -> Fri | I37: 0.70833333 | J37: 0.79166667 | K37: =ROUND((J37-I37)*24,2) -> 2 | L37: In this interactive workshop with UCL alumna Sara Mittica, you'll gain an insight into the world of museum collections and explore some of the challenges involved in balancing access, preservation, risk, resources and public benefit. | N37: 1-100 | O37: UCL Careers (uclcareers.targetconnect.net), captured 13-Oct-2026
A38: 30 | B38: 1 of 1 | C38: BCG UK International: Meet Our Global Offices | London | D38: Other / Employer-led event | E38: Not stated | G38: 46311 | H38: =TEXT(G38,"ddd") -> Fri | I38: 0.77083333 | J38: 0.85416667 | K38: =ROUND((J38-I38)*24,2) -> 2 | L38: Interested in starting your BCG career abroad? Join us in London to meet consultants and recruiters from BCG offices across Europe, Southeast Asia and the Caspian Region, and explore where an international career with BCG could take you. | N38: 1-100 | O38: UCL Careers (uclcareers.targetconnect.net), captured 13-Oct-2026
A39: 31 | B39: 1 of 2 | C39: Hong Kong · Global Talent & Career Showcase @London | D39: Other / Employer-led event | E39: Off Campus | F39: Off Campus | G39: 46312 | H39: =TEXT(G39,"ddd") -> Sat | I39: 0.4375 | J39: 0.70833333 | K39: =ROUND((J39-I39)*24,2) -> 6.5 | L39: Your Future in Hong Kong Starts Here | N39: 1-100 | O39: UCL Careers (uclcareers.targetconnect.net), captured 13-Oct-2026
A40: 31 | B40: 2 of 2 | C40: Hong Kong · Global Talent & Career Showcase @London | D40: Other / Employer-led event | E40: Off Campus | F40: Off Campus | G40: 46313 | H40: =TEXT(G40,"ddd") -> Sun | I40: 0.4375 | J40: 0.66666667 | K40: =ROUND((J40-I40)*24,2) -> 5.5 | L40: Your Future in Hong Kong Starts Here | N40: 1-100 | O40: UCL Careers (uclcareers.targetconnect.net), captured 13-Oct-2026
A41: 32 | B41: 1 of 1 | C41: On Campus Employer Pop-Up with : Deloitte | D41: Employer Presentation / Pop-Up | E41: On Campus | F41: On Campus: Wilkins Main Quad | G41: 46314 | H41: =TEXT(G41,"ddd") -> Mon | I41: 0.4375 | J41: 0.66666667 | K41: =ROUND((J41-I41)*24,2) -> 5.5 | L41: Want to learn more about what Deloitte is all about? We're inviting you to our "Meet Your Future" activation this autumn, to discover if a career with us could be right for you. | N41: 1-100 | O41: UCL Careers (uclcareers.targetconnect.net), captured 13-Oct-2026
A42: 33 | B42: 1 of 1 | C42: Career Essentials Group Work: Cover Letter Session | D42: Career Essentials Group Work | E42: Virtual | F42: Virtual event / Online webinar | G42: 46314 | H42: =TEXT(G42,"ddd") -> Mon | I42: 0.54166667 | J42: 0.57638889 | K42: =ROUND((J42-I42)*24,2) -> 0.83 | L42: Small group work Career Essentials session focusing on learning the key concepts that make up a good cover letter, reviewing your own work and providing peer-to-peer feedback. | N42: 1-100 | O42: UCL Careers (uclcareers.targetconnect.net), captured 13-Oct-2026
A43: 34 | B43: 1 of 1 | C43: PhD in the Life & Health Sciences Overview | D43: Life & Health Sciences | E43: Not stated | G43: 46314 | H43: =TEXT(G43,"ddd") -> Mon | I43: 0.54166667 | J43: 0.58333333 | K43: =ROUND((J43-I43)*24,2) -> 1 | L43: This session will provide an overview of doctoral study in the UK and help you explore your options before making an informed decision. The session will finish with a dedicated Q&A. | N43: 1-100 | O43: UCL Careers (uclcareers.targetconnect.net), captured 13-Oct-2026
A44: 35 | B44: 1 of 1 | C44: On Campus Employer Presentation: OIST - Okinawa Institute of Science and Technology | D44: Employer Presentation / Pop-Up | E44: On Campus | F44: On Campus: UCL Careers - 4th Floor Seminar Room (413) | G44: 46314 | H44: =TEXT(G44,"ddd") -> Mon | I44: 0.72916667 | J44: 0.79166667 | K44: =ROUND((J44-I44)*24,2) -> 1.5 | L44: Join us for an information session to learn about our fully funded research opportunities at Okinawa Institute of Science and Technology (OIST). | N44: 1-100 | O44: UCL Careers (uclcareers.targetconnect.net), captured 13-Oct-2026
A45: 36 | B45: 1 of 1 | C45: Career Lab - Using LinkedIn for a Purpose | D45: Career Lab | E45: On Campus | F45: On Campus: Canary Wharf Level 49, 49.02E Seminar Room | G45: 46315 | H45: =TEXT(G45,"ddd") -> Tue | I45: 0.39583333 | J45: 0.47916667 | K45: =ROUND((J45-I45)*24,2) -> 2 | L45: Learn how to to use LinkedIn to achieve a specific purpose through analysing scenarios and reflecting on success stories. | N45: 1-100 | O45: UCL Careers (uclcareers.targetconnect.net), captured 13-Oct-2026
A46: 37 | B46: 1 of 6 | C46: eCareersGrad MasterClass: Interview Success: Watch. Learn. Perform. | D46: eCareersGrad MasterClass | E46: Virtual | F46: Virtual event / Online webinar | G46: 46315 | H46: =TEXT(G46,"ddd") -> Tue | I46: 0.50694444 | J46: 0.54166667 | K46: =ROUND((J46-I46)*24,2) -> 0.83 | L46: An information session delivered by eCareersGrad with time for questions and answers. | N46: 1-100 | O46: UCL Careers (uclcareers.targetconnect.net), captured 13-Oct-2026
...

Sheet Summary
A1: UCL Careers events listing - summary (all figures are formulas over the 'All Sessions' sheet)
A3: Distinct events listed | B3: =MAX('All Sessions'!A2:A169) -> 153
A4: Scheduled sessions (rows) | B4: =COUNTA('All Sessions'!C2:C169) -> 168
A5: Earliest session | B5: =MIN('All Sessions'!G2:G169) -> 46303
A6: Latest session | B6: =MAX('All Sessions'!G2:G169) -> 46444
A8: Sessions by delivery mode | B8: Sessions
A9: Virtual | B9: =COUNTIF('All Sessions'!$E$2:$E$169,A9) -> 53
A10: On Campus | B10: =COUNTIF('All Sessions'!$E$2:$E$169,A10) -> 72
A11: Off Campus | B11: =COUNTIF('All Sessions'!$E$2:$E$169,A11) -> 8
A12: In person (venue listed) | B12: =COUNTIF('All Sessions'!$E$2:$E$169,A12) -> 1
A13: Not stated | B13: =COUNTIF('All Sessions'!$E$2:$E$169,A13) -> 34
A14: Total | B14: =SUM(B9:B13) -> 168
A16: Sessions by month | B16: Sessions
A17: Oct 2026 | B17: =COUNTIFS('All Sessions'!$G$2:$G$169,">="&DATE(2026,10,1),'All Sessions'!$G$2:$G$169,"<"&DATE(2026,11,1)) -> 97
A18: Nov 2026 | B18: =COUNTIFS('All Sessions'!$G$2:$G$169,">="&DATE(2026,11,1),'All Sessions'!$G$2:$G$169,"<"&DATE(2026,12,1)) -> 50
A19: Dec 2026 | B19: =COUNTIFS('All Sessions'!$G$2:$G$169,">="&DATE(2026,12,1),'All Sessions'!$G$2:$G$169,"<"&DATE(2027,1,1)) -> 15
A20: Jan 2027 | B20: =COUNTIFS('All Sessions'!$G$2:$G$169,">="&DATE(2027,1,1),'All Sessions'!$G$2:$G$169,"<"&DATE(2027,2,1)) -> 2
A21: Feb 2027 | B21: =COUNTIFS('All Sessions'!$G$2:$G$169,">="&DATE(2027,2,1),'All Sessions'!$G$2:$G$169,"<"&DATE(2027,3,1)) -> 4
A22: Total | B22: =SUM(B17:B21) -> 168
A24: Sessions by series / programme | B24: Sessions
A25: Career Essentials | B25: =COUNTIF('All Sessions'!$D$2:$D$169,A25) -> 26
A26: Career Essentials Group Work | B26: =COUNTIF('All Sessions'!$D$2:$D$169,A26) -> 15
A27: Career Lab | B27: =COUNTIF('All Sessions'!$D$2:$D$169,A27) -> 4
A28: Careers Fair | B28: =COUNTIF('All Sessions'!$D$2:$D$169,A28) -> 6
A29: Employer Presentation / Pop-Up | B29: =COUNTIF('All Sessions'!$D$2:$D$169,A29) -> 5
A30: Employer-led Skills Panel | B30: =COUNTIF('All Sessions'!$D$2:$D$169,A30) -> 3
A31: Employer-led Skills Programme | B31: =COUNTIF('All Sessions'!$D$2:$D$169,A31) -> 14
A32: Get Hired! | B32: =COUNTIF('All Sessions'!$D$2:$D$169,A32) -> 2
A33: International Students | B33: =COUNTIF('All Sessions'!$D$2:$D$169,A33) -> 6
A34: Life & Health Sciences | B34: =COUNTIF('All Sessions'!$D$2:$D$169,A34) -> 12
A35: Other / Employer-led event | B35: =COUNTIF('All Sessions'!$D$2:$D$169,A35) -> 49
A36: Sector Insights | B36: =COUNTIF('All Sessions'!$D$2:$D$169,A36) -> 2
... A39: eCareersGrad MasterClass | B39: =COUNTIF('All Sessions'!$D$2:$D$169,A39) -> 18
A40: Total | B40: =SUM(B25:B39) -> 168
A42: Notes
A43: Source: UCL Careers 'Search events' listing (153 results), two PDF captures dated 13-Oct-2026 21:52/21:53.
A44: One row per scheduled date; events offered on several dates (e.g. eCareersGrad MasterClasses) repeat with 'Session x of y'.
A45: 'Event Series / Programme' and 'Delivery Mode' are derived from the title and venue line respectively; all other fields are transcribed as listed.
A46: 'Delivery Mode' = 'Not stated' where the listing shows no venue/format line; 'In person (venue listed)' where a venue is given without an On/Off Campus label.
A47: 'Featured Organisation' records the sponsor logo shown beneath the description, where one appeared.
...
